Workbook

Sheet Direcional Expansão
A1: PCA (ANÁLISE DE COMPONENTE PRINCIPAL) - 3 componentes
A2: Cód | B2: Município | C2: UF | D2: N° FSJ | E2: Ass. por ambos | F2: Aquisição | G2: Ampliação | H2: Assinado por proprietário | I2: Contratos | J2: Venda > 500k | K2: Média Faturamento | L2: %Share | M2: Demanda | N2: População | O2: Porte da cidade | P2: REGIÃO GEOGRÁFICA IMEDIATA | Q2: REGIÃO GEOGRÁFICA INTERMEDIÁRIA | R2: Taxa Crescimento Pop | S2: Taxa Crescimento Dom | T2: Concorrência | U2: Lojas Cabem | V2: PIB | W2: Renda Média Domiciliar (SM) | X2: Fator 1 | Y2: Fator 2 | Z2: Fator 3 | AA2: Ranking | AB2: Status | AC2: Região Imediata
A3: 410690 | B3: Curitiba | C3: PR | D3: 4 | E3: =COUNTIFS('Contratos assinados '!F:F,'Direcional Expansão'!B3,'Contratos assinados '!J:J, "Assinado por ambos") -> 0 | F3: =COUNTIFS('Contratos assinados '!F:F,'Direcional Expansão'!B3,'Contratos assinados '!J:J,"Aquisição") -> 0 | G3: =COUNTIFS('Contratos assinados '!F:F,'Direcional Expansão'!B3,'Contratos assinados '!J:J,"Ampliação") -> 0 | H3: =COUNTIFS('Contratos assinados '!F:F,'Direcional Expansão'!B3,'Contratos assinados '!J:J,"Assinado por proprietário") -> 0 | I3: =SUM(E3:H3) -> 0 | J3: =IF(D3=0, "-", COUNTIFS('Base Lojas'!B:B, A3, 'Base Lojas'!I:I, ">500000")/D3) -> 0.5 | K3: 529473.24 | L3: 0.006059215 | M3: 3.4953256e+08 | N3: 1773733 | O3: =_xlfn.XLOOKUP(A3,Cidades!A:A,Cidades!D:D) -> Maior que 200k | P3: =_xlfn.XLOOKUP(A3,'[1]1° RAIZ'!$A:$A,'[1]1° RAIZ'!$AH:$AH) -> Curitiba | Q3: =_xlfn.XLOOKUP(A3,'[1]1° RAIZ'!$A:$A,'[1]1° RAIZ'!$AE:$AE) -> Curitiba | R3: 1.1734469e-05 | S3: 0.0061701967 | T3: 760 | U3: 113 | V3: 59976.102 | W3: 7.4815934 | X3: 23.530133 | Y3: -6.6132887 | Z3: -1.4440723 | AA3: 8.9042361 | AB3: =IF(B3="Capão do Leão","Erro IBGE", IF(AND(U3<=0,M3<=2000000),"Mercado insuficiente", IF(U3<=0,"Limite de expansão", IF(K3<500000,"Performance", IF(M3<=2000000,"Mercado insuficiente","Expansão") ) ) ) ) -> Expansão | AC3: =IF(P3=B3,"Oportunidade","Validar") -> Oportunidade
A4: 420910 | B4: Joinville | C4: SC | D4: 4 | E4: =COUNTIFS('Contratos assinados '!F:F,'Direcional Expansão'!B4,'Contratos assinados '!J:J, "Assinado por ambos") -> 0 | F4: =COUNTIFS('Contratos assinados '!F:F,'Direcional Expansão'!B4,'Contratos assinados '!J:J,"Aquisição") -> 0 | G4: =COUNTIFS('Contratos assinados '!F:F,'Direcional Expansão'!B4,'Contratos assinados '!J:J,"Ampliação") -> 0 | H4: =COUNTIFS('Contratos assinados '!F:F,'Direcional Expansão'!B4,'Contratos assinados '!J:J,"Assinado por proprietário") -> 0 | I4: =SUM(E4:H4) -> 0 | J4: =IF(D4=0, "-", COUNTIFS('Base Lojas'!B:B, A4, 'Base Lojas'!G:G, ">500000")/D4) -> 0.5 | K4: 473206.54 | L4: 0.016675383 | M4: 1.1351021e+08 | N4: 616323 | O4: =_xlfn.XLOOKUP(A4,Cidades!A:A,Cidades!D:D) -> Maior que 200k | P4: =_xlfn.XLOOKUP(A4,'[1]1° RAIZ'!$A:$A,'[1]1° RAIZ'!$AH:$AH) -> Joinville | Q4: =_xlfn.XLOOKUP(A4,'[1]1° RAIZ'!$A:$A,'[1]1° RAIZ'!$AE:$AE) -> Joinville | R4: 0.00013873741 | S4: 0.015512934 | T4: 228 | U4: 36 | V4: 75898.327 | W4: 5.6415158 | X4: 7.5371564 | Y4: -1.1918205 | Z4: -0.53373233 | AA4: 2.9774401 | AB4: =IF(B4="Capão do Leão","Erro IBGE", IF(AND(U4<=0,M4<=2000000),"Mercado insuficiente", IF(U4<=0,"Limite de expansão", IF(K4<500000,"Performance", IF(M4<=2000000,"Mercado insuficiente","Expansão") ) ) ) ) -> Performance | AC4: =IF(P4=B4,"Oportunidade","Validar") -> Oportunidade
A5: 411990 | B5: Ponta Grossa | C5: PR | D5: 0 | E5: =COUNTIFS('Contratos assinados '!F:F,'Direcional Expansão'!B5,'Contratos assinados '!J:J, "Assinado por ambos") -> 0 | F5: =COUNTIFS('Contratos assinados '!F:F,'Direcional Expansão'!B5,'Contratos assinados '!J:J,"Aquisição") -> 0 | G5: =COUNTIFS('Contratos assinados '!F:F,'Direcional Expansão'!B5,'Contratos assinados '!J:J,"Ampliação") -> 0 | H5: =COUNTIFS('Contratos assinados '!F:F,'Direcional Expansão'!B5,'Contratos assinados '!J:J,"Assinado por proprietário") -> 0 | I5: =SUM(E5:H5) -> 0 | J5: =IF(D5=0, "-", COUNTIFS('Base Lojas'!B:B, A5, 'Base Lojas'!I:I, ">500000")/D5) -> - | K5: - | L5: 0 | M5: 52309124 | N5: 358367 | O5: =_xlfn.XLOOKUP(A5,Cidades!A:A,Cidades!D:D) -> Maior que 200k | P5: =_xlfn.XLOOKUP(A5,'[1]1° RAIZ'!$A:$A,'[1]1° RAIZ'!$AH:$AH) -> Ponta Grossa | Q5: =_xlfn.XLOOKUP(A5,'[1]1° RAIZ'!$A:$A,'[1]1° RAIZ'!$AE:$AE) -> Ponta Grossa | R5: 0.00010790575 | S5: 0.015582368 | T5: 109 | U5: 23 | V5: 58329.645 | W5: 4.495249 | X5: 3.9681546 | Y5: -0.78599628 | Z5: -0.73897544 | AA5: 1.4924571 | AB5: =IF(B5="Capão do Leão","Erro IBGE", IF(AND(U5<=0,M5<=2000000),"Mercado insuficiente", IF(U5<=0,"Limite de expansão", IF(K5<500000,"Performance", IF(M5<=2000000,"Mercado insuficiente","Expansão") ) ) ) ) -> Expansão | AC5: =IF(P5=B5,"Oportunidade","Validar") -> Oportunidade
A6: 412550 | B6: São José dos Pinhais | C6: PR | D6: 0 | E6: =COUNTIFS('Contratos assinados '!F:F,'Direcional Expansão'!B6,'Contratos assinados '!J:J, "Assinado por ambos") -> 0 | F6: =COUNTIFS('Contratos assinados '!F:F,'Direcional Expansão'!B6,'Contratos assinados '!J:J,"Aquisição") -> 0 | G6: =COUNTIFS('Contratos assinados '!F:F,'Direcional Expansão'!B6,'Contratos assinados '!J:J,"Ampliação") -> 0 | H6: =COUNTIFS('Contratos assinados '!F:F,'Direcional Expansão'!B6,'Contratos assinados '!J:J,"Assinado por proprietário") -> 0 | I6: =SUM(E6:H6) -> 0 | J6: =IF(D6=0, "-", COUNTIFS('Base Lojas'!B:B, A6, 'Base Lojas'!I:I, ">500000")/D6) -> - | K6: - | L6: 0 | M6: 45151280 | N6: 329222 | O6: =_xlfn.XLOOKUP(A6,Cidades!A:A,Cidades!D:D) -> Maior que 200k | P6: =_xlfn.XLOOKUP(A6,'[1]1° RAIZ'!$A:$A,'[1]1° RAIZ'!$AH:$AH) -> Curitiba | Q6: =_xlfn.XLOOKUP(A6,'[1]1° RAIZ'!$A:$A,'[1]1° RAIZ'!$AE:$AE) -> Curitiba | R6: 0.00017280257 | S6: 0.020583707 | T6: 129 | U6: 21 | V6: 86698.641 | W6: 4.3486417 | X6: 3.8143556 | Y6: -0.36303554 | Z6: -0.40662252 | AA6: 1.5257804 | AB6: =IF(B6="Capão do Leão","Erro IBGE", IF(AND(U6<=0,M6<=2000000),"Mercado insuficiente", IF(U6<=0,"Limite de expansão", IF(K6<500000,"Performance", IF(M6<=2000000,"Mercado insuficiente","Expansão") ) ) ) ) -> Expansão | AC6: =IF(P6=B6,"Oportunidade","Validar") -> Validar
A7: 411370 | B7: Londrina | C7: PR | D7: 16 | E7: =COUNTIFS('Contratos assinados '!F:F,'Direcional Expansão'!B7,'Contratos assinados '!J:J, "Assinado por ambos") -> 0 | F7: =COUNTIFS('Contratos assinados '!F:F,'Direcional Expansão'!B7,'Contratos assinados '!J:J,"Aquisição") -> 0 | G7: =COUNTIFS('Contratos assinados '!F:F,'Direcional Expansão'!B7,'Contratos assinados '!J:J,"Ampliação") -> 0 | H7: =COUNTIFS('Contratos assinados '!F:F,'Direcional Expansão'!B7,'Contratos assinados '!J:J,"Assinado por proprietário") -> 0 | I7: =SUM(E7:H7) -> 0 | J7: =IF(D7=0, "-", COUNTIFS('Base Lojas'!B:B, A7, 'Base Lojas'!G:G, ">500000")/D7) -> 0.3125 | K7: 450156.55 | L7: 0.076176118 | M7: 94550694 | N7: 555937 | O7: =_xlfn.XLOOKUP(A7,Cidades!A:A,Cidades!D:D) -> Maior que 200k | P7: =_xlfn.XLOOKUP(A7,'[1]1° RAIZ'!$A:$A,'[1]1° RAIZ'!$AH:$AH) -> Londrina | Q7: =_xlfn.XLOOKUP(A7,'[1]1° RAIZ'!$A:$A,'[1]1° RAIZ'!$AE:$AE) -> Londrina | R7: 7.1674423e-05 | S7: 0.010994379 | T7: 183 | U7: 20 | V7: 45612.287 | W7: 5.186494 | X7: 5.724654 | Y7: -1.0124124 | Z7: -0.3783049 | AA7: 2.2491 | AB7: =IF(B7="Capão do Leão","Erro IBGE", IF(AND(U7<=0,M7<=2000000),"Mercado insuficiente", IF(U7<=0,"Limite de expansão", IF(K7<500000,"Performance", IF(M7<=2000000,"Mercado insuficiente","Expansão") ) ) ) ) -> Performance | AC7: =IF(P7=B7,"Oportunidade","Validar") -> Oportunidade
A8: 420540 | B8: Florianópolis | C8: SC | D8: 18 | E8: =COUNTIFS('Contratos assinados '!F:F,'Direcional Expansão'!B8,'Contratos assinados '!J:J, "Assinado por ambos") -> 0 | F8: =COUNTIFS('Contratos assinados '!F:F,'Direcional Expansão'!B8,'Contratos assinados '!J:J,"Aquisição") -> 0 | G8: =COUNTIFS('Contratos assinados '!F:F,'Direcional Expansão'!B8,'Contratos assinados '!J:J,"Ampliação") -> 0 | H8: =COUNTIFS('Contratos assinados '!F:F,'Direcional Expansão'!B8,'Contratos assinados '!J:J,"Assinado por proprietário") -> 0 | I8: =SUM(E8:H8) -> 0 | J8: =IF(D8=0, "-", COUNTIFS('Base Lojas'!B:B, A8, 'Base Lojas'!I:I, ">500000")/D8) -> 0.77777778 | K8: 884907.8 | L8: 0.12015389 | M8: 1.3256616e+08 | N8: 537213 | O8: =_xlfn.XLOOKUP(A8,Cidades!A:A,Cidades!D:D) -> Maior que 200k | P8: =_xlfn.XLOOKUP(A8,'[1]1° RAIZ'!$A:$A,'[1]1° RAIZ'!$AH:$AH) -> Florianópolis | Q8: =_xlfn.XLOOKUP(A8,'[1]1° RAIZ'!$A:$A,'[1]1° RAIZ'!$AE:$AE) -> Florianópolis | R8: 0.00018890029 | S8: 0.020340133 | T8: 237 | U8: 17 | V8: 44854.646 | W8: 8.0222292 | X8: 6.879443 | Y8: 0.53207887 | Z8: -0.33951717 | AA8: 2.9676422 | AB8: =IF(B8="Capão do Leão","Erro IBGE", IF(AND(U8<=0,M8<=2000000),"Mercado insuficiente", IF(U8<=0,"Limite de expansão", IF(K8<500000,"Performance", IF(M8<=2000000,"Mercado insuficiente","Expansão") ) ) ) ) -> Expansão | AC8: =IF(P8=B8,"Oportunidade","Validar") -> Oportunidade
A9: 420240 | B9: Blumenau | C9: SC | D9: 6 | E9: =COUNTIFS('Contratos assinados '!F:F,'Direcional Expansão'!B9,'Contratos assinados '!J:J, "Assinado por ambos") -> 1 | F9: =COUNTIFS('Contratos assinados '!F:F,'Direcional Expansão'!B9,'Contratos assinados '!J:J,"Aquisição") -> 0 | G9: =COUNTIFS('Contratos assinados '!F:F,'Direcional Expansão'!B9,'Contratos assinados '!J:J,"Ampliação") -> 0 | H9: =COUNTIFS('Contratos assinados '!F:F,'Direcional Expansão'!B9,'Contratos assinados '!J:J,"Assinado por proprietário") -> 0 | I9: =SUM(E9:H9) -> 1 | J9: =IF(D9=0, "-", COUNTIFS('Base Lojas'!B:B, A9, 'Base Lojas'!G:G, ">500000")/D9) -> 0.16666667 | K9: 399569.23 | L9: 0.030600313 | M9: 78346106 | N9: 361261 | O9: =_xlfn.XLOOKUP(A9,Cidades!A:A,Cidades!D:D) -> Maior que 200k | P9: =_xlfn.XLOOKUP(A9,'[1]1° RAIZ'!$A:$A,'[1]1° RAIZ'!$AH:$AH) -> Blumenau | Q9: =_xlfn.XLOOKUP(A9,'[1]1° RAIZ'!$A:$A,'[1]1° RAIZ'!$AE:$AE) -> Blumenau | R9: 0.00012038587 | S9: 0.014892859 | T9: 134 | U9: 17 | V9: 59879.071 | W9: 5.9650006 | X9: 4.416656 | Y9: 0.034937689 | Z9: -0.42486282 | AA9: 1.8374896 | AB9: =IF(B9="Capão do Leão","Erro IBGE", IF(AND(U9<=0,M9<=2000000),"Mercado insuficiente", IF(U9<=0,"Limite de expansão", IF(K9<500000,"Performance", IF(M9<=2000000,"Mercado insuficiente","Expansão") ) ) ) ) -> Performance | AC9: =IF(P9=B9,"Oportunidade","Validar") -> Oportunidade
A10: 410480 | B10: Cascavel | C10: PR | D10: 6 | E10: =COUNTIFS('Contratos assinados '!F:F,'Direcional Expansão'!B10,'Contratos assinados '!J:J, "Assinado por ambos") -> 0 | F10: =COUNTIFS('Contratos assinados '!F:F,'Direcional Expansão'!B10,'Contratos assinados '!J:J,"Aquisição") -> 0 | G10: =COUNTIFS('Contratos assinados '!F:F,'Direcional Expansão'!B10,'Contratos assinados '!J:J,"Ampliação") -> 0 | H10: =COUNTIFS('Contratos assinados '!F:F,'Direcional Expansão'!B10,'Contratos assinados '!J:J,"Assinado por proprietário") -> 0 | I10: =SUM(E10:H10) -> 0 | J10: =IF(D10=0, "-", COUNTIFS('Base Lojas'!B:B, A10, 'Base Lojas'!G:G, ">500000")/D10) -> 0.33333333 | K10: 499028.02 | L10: 0.051856357 | M10: 57739655 | N10: 348051 | O10: =_xlfn.XLOOKUP(A10,Cidades!A:A,Cidades!D:D) -> Maior que 200k | P10: =_xlfn.XLOOKUP(A10,'[1]1° RAIZ'!$A:$A,'[1]1° RAIZ'!$AH:$AH) -> Cascavel | Q10: =_xlfn.XLOOKUP(A10,'[1]1° RAIZ'!$A:$A,'[1]1° RAIZ'!$AE:$AE) -> Cascavel | R10: 0.00015172098 | S10: 0.019428703 | T10: 129 | U10: 17 | V10: 48193.639 | W10: 4.8722281 | X10: 3.8938653 | Y10: -0.39791193 | Z10: -0.68214471 | AA10: 1.5231674 | AB10: =IF(B10="Capão do Leão","Erro IBGE", IF(AND(U10<=0,M10<=2000000),"Mercado insuficiente", IF(U10<=0,"Limite de expansão", IF(K10<500000,"Performance", IF(M10<=2000000,"Mercado insuficiente","Expansão") ) ) ) ) -> Performance | AC10: =IF(P10=B10,"Oportunidade","Validar") -> Oportunidade
A11: 410580 | B11: Colombo | C11: PR | D11: 0 | E11: =COUNTIFS('Contratos assinados '!F:F,'Direcional Expansão'!B11,'Contratos assinados '!J:J, "Assinado por ambos") -> 0 | F11: =COUNTIFS('Contratos assinados '!F:F,'Direcional Expansão'!B11,'Contratos assinados '!J:J,"Aquisição") -> 0 | G11: =COUNTIFS('Contratos assinados '!F:F,'Direcional Expansão'!B11,'Contratos assinados '!J:J,"Ampliação") -> 0 | H11: =COUNTIFS('Contratos assinados '!F:F,'Direcional Expansão'!B11,'Contratos assinados '!J:J,"Assinado por proprietário") -> 0 | I11: =SUM(E11:H11) -> 0 | J11: =IF(D11=0, "-", COUNTIFS('Base Lojas'!B:B, A11, 'Base Lojas'!I:I, ">500000")/D11) -> - | K11: - | L11: 0 | M11: 29870151 | N11: 232056 | O11: =_xlfn.XLOOKUP(A11,Cidades!A:A,Cidades!D:D) -> Maior que 200k | P11: =_xlfn.XLOOKUP(A11,'[1]1° RAIZ'!$A:$A,'[1]1° RAIZ'!$AH:$AH) -> Curitiba | Q11: =_xlfn.XLOOKUP(A11,'[1]1° RAIZ'!$A:$A,'[1]1° RAIZ'!$AE:$AE) -> Curitiba | R11: 6.6032292e-05 | S11: 0.011526628 | T11: 74 | U11: 15 | V11: 26402.994 | W11: 3.5680095 | X11: 2.3689253 | Y11: -1.1012465 | Z11: -1.0623745 | AA11: 0.72908048 | AB11: =IF(B11="Capão do Leão","Erro IBGE", IF(AND(U11<=0,M11<=2000000),"Mercado insuficiente", IF(U11<=0,"Limite de expansão", IF(K11<500000,"Performance", IF(M11<=2000000,"Mercado insuficiente","Expansão") ) ) ) ) -> Expansão | AC11: =IF(P11=B11,"Oportunidade","Validar") -> Validar
A12: 411520 | B12: Maringá | C12: PR | D12: 16 | E12: =COUNTIFS('Contratos assinados '!F:F,'Direcional Expansão'!B12,'Contratos assinados '!J:J, "Assinado por ambos") -> 1 | F12: =COUNTIFS('Contratos assinados '!F:F,'Direcional Expansão'!B12,'Contratos assinados '!J:J,"Aquisição") -> 0 | G12: =COUNTIFS('Contratos assinados '!F:F,'Direcional Expansão'!B12,'Contratos assinados '!J:J,"Ampliação") -> 0 | H12: =COUNTIFS('Contratos assinados '!F:F,'Direcional Expansão'!B12,'Contratos assinados '!J:J,"Assinado por proprietário") -> 0 | I12: =SUM(E12:H12) -> 1 | J12: =IF(D12=0, "-", COUNTIFS('Base Lojas'!B:B, A12, 'Base Lojas'!G:G, ">500000")/D12) -> 0.1875 | K12: 368659.03 | L12: 0.080085143 | M12: 73653417 | N12: 409657 | O12: =_xlfn.XLOOKUP(A12,Cidades!A:A,Cidades!D:D) -> Maior que 200k | P12: =_xlfn.XLOOKUP(A12,'[1]1° RAIZ'!$A:$A,'[1]1° RAIZ'!$AH:$AH) -> Maringá | Q12: =_xlfn.XLOOKUP(A12,'[1]1° RAIZ'!$A:$A,'[1]1° RAIZ'!$AE:$AE) -> Maringá | R12: 0.00010614147 | S12: 0.014936784 | T12: 152 | U12: 11 | V12: 59294.088 | W12: 5.7430176 | X12: 4.2750996 | Y12: 0.088244137 | Z12: -0.10896035 | AA12: 1.820941 | AB12: =IF(B12="Capão do Leão","Erro IBGE", IF(AND(U12<=0,M12<=2000000),"Mercado insuficiente", IF(U12<=0,"Limite de expansão", IF(K12<500000,"Performance", IF(M12<=2000000,"Mercado insuficiente","Expansão") ) ) ) ) -> Performance | AC12: =IF(P12=B12,"Oportunidade","Validar") -> Oportunidade
A13: 421660 | B13: São José | C13: SC | D13: 7 | E13: =COUNTIFS('Contratos assinados '!F:F,'Direcional Expansão'!B13,'Contratos assinados '!J:J, "Assinado por ambos") -> 1 | F13: =COUNTIFS('Contratos assinados '!F:F,'Direcional Expansão'!B13,'Contratos assinados '!J:J,"Aquisição") -> 0 | G13: =COUNTIFS('Contratos assinados '!F:F,'Direcional Expansão'!B13,'Contratos assinados '!J:J,"Ampliação") -> 0 | H13: =COUNTIFS('Contratos assinados '!F:F,'Direcional Expansão'!B13,'Contratos assinados '!J:J,"Assinado por proprietário") -> 0 | I13: =SUM(E13:H13) -> 1 | J13: =IF(D13=0, "-", COUNTIFS('Base Lojas'!B:B, A13, 'Base Lojas'!G:G, ">500000")/D13) -> 0.42857143 | K13: 477121.93 | L13: 0.058758649 | M13: 56840203 | N13: 270295 | O13: =_xlfn.XLOOKUP(A13,Cidades!A:A,Cidades!D:D) -> Maior que 200k | P13: =_xlfn.XLOOKUP(A13,'[1]1° RAIZ'!$A:$A,'[1]1° RAIZ'!$AH:$AH) -> Florianópolis | Q13: =_xlfn.XLOOKUP(A13,'[1]1° RAIZ'!$A:$A,'[1]1° RAIZ'!$AE:$AE) -> Florianópolis | R13: 0.00019414248 | S13: 0.021606297 | T13: 100 | U13: 10 | V13: 52385.161 | W13: 5.4429226 | X13: 3.0875136 | Y13: 0.39455517 | Z13: -0.53957272 | AA13: 1.3101021 | AB13: =IF(B13="Capão do Leão","Erro IBGE", IF(AND(U13<=0,M13<=2000000),"Mercado insuficiente", IF(U13<=0,"Limite de expansão", IF(K13<500000,"Performance", IF(M13<=2000000,"Mercado insuficiente","Expansão") ) ) ) ) -> Performance | AC13: =IF(P13=B13,"Oportunidade","Validar") -> Validar
A14: 410940 | B14: Guarapuava | C14: PR | D14: 2 | E14: =COUNTIFS('Contratos assinados '!F:F,'Direcional Expansão'!B14,'Contratos assinados '!J:J, "Assinado por ambos") -> 1 | F14: =COUNTIFS('Contratos assinados '!F:F,'Direcional Expansão'!B14,'Contratos assinados '!J:J,"Aquisição") -> 0 | G14: =COUNTIFS('Contratos assinados '!F:F,'Direcional Expansão'!B14,'Contratos assinados '!J:J,"Ampliação") -> 0 | H14: =COUNTIFS('Contratos assinados '!F:F,'Direcional Expansão'!B14,'Contratos assinados '!J:J,"Assinado por proprietário") -> 0 | I14: =SUM(E14:H14) -> 1 | J14: =IF(D14=0, "-", COUNTIFS('Base Lojas'!B:B, A14, 'Base Lojas'!I:I, ">500000")/D14) -> 0.5 | K14: 516079.9 | L14: 0.042569286 | M14: 24246585 | N14: 182093 | O14: =_xlfn.XLOOKUP(A14,Cidades!A:A,Cidades!D:D) -> Entre 150k e 200k | P14: =_xlfn.XLOOKUP(A14,'[1]1° RAIZ'!$A:$A,'[1]1° RAIZ'!$AH:$AH) -> Guarapuava | Q14: =_xlfn.XLOOKUP(A14,'[1]1° RAIZ'!$A:$A,'[1]1° RAIZ'!$AE:$AE) -> Guarapuava | R14: 6.4634999e-05 | S14: 0.010953216 | T14: 65 | U14: 10 | V14: 49171.471 | W14: 3.871627 | X14: 1.8233473 | Y14: -0.42327467 | Z14: -0.45826001 | AA14: 0.66328436 | AB14: =IF(B14="Capão do Leão","Erro IBGE", IF(AND(U14<=0,M14<=2000000),"Mercado insuficiente", IF(U14<=0,"Limite de expansão", IF(K14<500000,"Performance", IF(M14<=2000000,"Mercado insuficiente","Expansão") ) ) ) ) -> Expansão | AC14: =IF(P14=B14,"Oportunidade","Validar") -> Oportunidade
A15: 420820 | B15: Itajaí | C15: SC | D15: 8 | E15: =COUNTIFS('Contratos assinados '!F:F,'Direcional Expansão'!B15,'Contratos assinados '!J:J, "Assinado por ambos") -> 0 | F15: =COUNTIFS('Contratos assinados '!F:F,'Direcional Expansão'!B15,'Contratos assinados '!J:J,"Aquisição") -> 0 | G15: =COUNTIFS('Contratos assinados '!F:F,'Direcional Expansão'!B15,'Contratos assinados '!J:J,"Ampliação") -> 1 | H15: =COUNTIFS('Contratos assinados '!F:F,'Direcional Expansão'!B15,'Contratos assinados '!J:J,"Assinado por proprietário") -> 0 | I15: =SUM(E15:H15) -> 1 | J15: =IF(D15=0, "-", COUNTIFS('Base Lojas'!B:B, A15, 'Base Lojas'!I:I, ">500000")/D15) -> 0.75 | K15: 639106.45 | L15: 0.10154863 | M15: 50348798 | N15: 264054 | O15: =_xlfn.XLOOKUP(A15,Cidades!A:A,Cidades!D:D) -> Maior que 200k | P15: =_xlfn.XLOOKUP(A15,'[1]1° RAIZ'!$A:$A,'[1]1° RAIZ'!$AH:$AH) -> Itajaí | Q15: =_xlfn.XLOOKUP(A15,'[1]1° RAIZ'!$A:$A,'[1]1° RAIZ'!$AE:$AE) -> Blumenau | R15: 0.00028439155 | S15: 0.027286013 | T15: 105 | U15: 9 | V15: 181166.23 | W15: 5.0486227 | X15: 2.9610387 | Y15: 1.7575112 | Z15: 1.4836989 | AA15: 1.6834055 | AB15: =IF(B15="Capão do Leão","Erro IBGE", IF(AND(U15<=0,M15<=2000000),"Mercado insuficiente", IF(U15<=0,"Limite de expansão", IF(K15<500000,"Performance", IF(M15<=2000000,"Mercado insuficiente","Expansão") ) ) ) ) -> Expansão | AC15: =IF(P15=B15,"Oportunidade","Validar") -> Oportunidade
A16: 420420 | B16: Chapecó | C16: SC | D16: 7 | E16: =COUNTIFS('Contratos assinados '!F:F,'Direcional Expansão'!B16,'Contratos assinados '!J:J, "Assinado por ambos") -> 0 | F16: =COUNTIFS('Contratos assinados '!F:F,'Direcional Expansão'!B16,'Contratos assinados '!J:J,"Aquisição") -> 0 | G16: =COUNTIFS('Contratos assinados '!F:F,'Direcional Expansão'!B16,'Contratos assinados '!J:J,"Ampliação") -> 0 | H16: =COUNTIFS('Contratos assinados '!F:F,'Direcional Expansão'!B16,'Contratos assinados '!J:J,"Assinado por proprietário") -> 0 | I16: =SUM(E16:H16) -> 0 | J16: =IF(D16=0, "-", COUNTIFS('Base Lojas'!B:B, A16, 'Base Lojas'!I:I, ">500000")/D16) -> 0.57142857 | K16: 501567.47 | L16: 0.079815749 | M16: 43988465 | N16: 254781 | O16: =_xlfn.XLOOKUP(A16,Cidades!A:A,Cidades!D:D) -> Maior que 200k | P16: =_xlfn.XLOOKUP(A16,'[1]1° RAIZ'!$A:$A,'[1]1° RAIZ'!$AH:$AH) -> Chapecó | Q16: =_xlfn.XLOOKUP(A16,'[1]1° RAIZ'!$A:$A,'[1]1° RAIZ'!$AE:$AE) -> Chapecó | R16: 0.00025540503 | S16: 0.02501592 | T16: 100 | U16: 9 | V16: 54201.449 | W16: 4.9208035 | X16: 2.735713 | Y16: 0.4019574 | Z16: -0.57833914 | AA16: 1.1569171 | AB16: =IF(B16="Capão do Leão","Erro IBGE", IF(AND(U16<=0,M16<=2000000),"Mercado insuficiente", IF(U16<=0,"Limite de expansão", IF(K16<500000,"Performance", IF(M16<=2000000,"Mercado insuficiente","Expansão") ) ) ) ) -> Expansão | AC16: =IF(P16=B16,"Oportunidade","Validar") -> Oportunidade
A17: 420890 | B17: Jaraguá do Sul | C17: SC | D17: 3 | E17: =COUNTIFS('Contratos assinados '!F:F,'Direcional Expansão'!B17,'Contratos assinados '!J:J, "Assinado por ambos") -> 0 | F17: =COUNTIFS('Contratos assinados '!F:F,'Direcional Expansão'!B17,'Contratos assinados '!J:J,"Aquisição") -> 0 | G17: =COUNTIFS('Contratos assinados '!F:F,'Direcional Expansão'!B17,'Contratos assinados '!J:J,"Ampliação") -> 0 | H17: =COUNTIFS('Contratos assinados '!F:F,'Direcional Expansão'!B17,'Contratos assinados '!J:J,"Assinado por proprietário") -> 0 | I17: =SUM(E17:H17) -> 0 | J17: =IF(D17=0, "-", COUNTIFS('Base Lojas'!B:B, A17, 'Base Lojas'!G:G, ">500000")/D17) -> 0.33333333 | K17: 459276.87 | L17: 0.040100084 | M17: 34359794 | N17: 182660 | O17: =_xlfn.XLOOKUP(A17,Cidades!A:A,Cidades!D:D) -> Entre 150k e 200k | P17: =_xlfn.XLOOKUP(A17,'[1]1° RAIZ'!$A:$A,'[1]1° RAIZ'!$AH:$AH) -> Joinville | Q17: =_xlfn.XLOOKUP(A17,'[1]1° RAIZ'!$A:$A,'[1]1° RAIZ'!$AE:$AE) -> Joinville | R17: 0.00018894934 | S17: 0.019594958 | T17: 92 | U17: 9 | V17: 67610.974 | W17: 5.4838698 | X17: 2.3618351 | Y17: 0.74617975 | Z17: -0.38126763 | AA17: 1.0697355 | AB17: =IF(B17="Capão do Leão","Erro IBGE", IF(AND(U17<=0,M17<=2000000),"Mercado insuficiente", IF(U17<=0,"Limite de expansão", IF(K17<500000,"Performance", IF(M17<=2000000,"Mercado insuficiente","Expansão") ) ) ) ) -> Performance | AC17: =IF(P17=B17,"Oportunidade","Validar") -> Validar
A18: 410180 | B18: Araucária | C18: PR | D18: 1 | E18: =COUNTIFS('Contratos assinados '!F:F,'Direcional Expansão'!B18,'Contratos assinados '!J:J, "Assinado por ambos") -> 0 | F18: =COUNTIFS('Contratos assinados '!F:F,'Direcional Expansão'!B18,'Contratos assinados '!J:J,"Aquisição") -> 0 | G18: =COUNTIFS('Contratos assinados '!F:F,'Direcional Expansão'!B18,'Contratos assinados '!J:J,"Ampliação") -> 0 | H18: =COUNTIFS('Contratos assinados '!F:F,'Direcional Expansão'!B18,'Contratos assinados '!J:J,"Assinado por proprietário") -> 0 | I18: =SUM(E18:H18) -> 0 | J18: =IF(D18=0, "-", COUNTIFS('Base Lojas'!B:B, A18, 'Base Lojas'!I:I, ">500000")/D18) -> 1 | K18: 511004.74 | L18: 0.024332456 | M18: 21000952 | N18: 151666 | O18: =_xlfn.XLOOKUP(A18,Cidades!A:A,Cidades!D:D) -> Entre 150k e 200k | P18: =_xlfn.XLOOKUP(A18,'[1]1° RAIZ'!$A:$A,'[1]1° RAIZ'!$AH:$AH) -> Curitiba | Q18: =_xlfn.XLOOKUP(A18,'[1]1° RAIZ'!$A:$A,'[1]1° RAIZ'!$AE:$AE) -> Curitiba | R18: 0.00018697202 | S18: 0.022555882 | T18: 40 | U18: 9 | V18: 174727.8 | W18: 4.2958383 | X18: 1.5297908 | Y18: 1.4227987 | Z18: 1.2175216 | AA18: 0.99529999 | AB18: =IF(B18="Capão do Leão","Erro IBGE", IF(AND(U18<=0,M18<=2000000),"Mercado insuficiente", IF(U18<=0,"Limite de expansão", IF(K18<500000,"Performance", IF(M18<=2000000,"Mercado insuficiente","Expansão") ) ) ) ) -> Expansão | AC18: =IF(P18=B18,"Oportunidade","Validar") -> Validar
A19: 421190 | B19: Palhoça | C19: SC | D19: 5 | E19: =COUNTIFS('Contratos assinados '!F:F,'Direcional Expansão'!B19,'Contratos assinados '!J:J, "Assinado por ambos") -> 1 | F19: =COUNTIFS('Contratos assinados '!F:F,'Direcional Expansão'!B19,'Contratos assinados '!J:J,"Aquisição") -> 0 | G19: =COUNTIFS('Contratos assinados '!F:F,'Direcional Expansão'!B19,'Contratos assinados '!J:J,"Ampliação") -> 0 | H19: =COUNTIFS('Contratos assinados '!F:F,'Direcional Expansão'!B19,'Contratos assinados '!J:J,"Assinado por proprietário") -> 0 | I19: =SUM(E19:H19) -> 1 | J19: =IF(D19=0, "-", COUNTIFS('Base Lojas'!B:B, A19, 'Base Lojas'!G:G, ">500000")/D19) -> 0.4 | K19: 493436.91 | L19: 0.064238482 | M19: 38406644 | N19: 222598 | O19: =_xlfn.XLOOKUP(A19,Cidades!A:A,Cidades!D:D) -> Maior que 200k | P19: =_xlfn.XLOOKUP(A19,'[1]1° RAIZ'!$A:$A,'[1]1° RAIZ'!$AH:$AH) -> Florianópolis | Q19: =_xlfn.XLOOKUP(A19,'[1]1° RAIZ'!$A:$A,'[1]1° RAIZ'!$AE:$AE) -> Florianópolis | R19: 0.00037927329 | S19: 0.03776951 | T19: 76 | U19: 9 | V19: 36199.948 | W19: 4.2944095 | X19: 2.2931288 | Y19: 0.30369951 | Z19: -1.2451161 | AA19: 0.87816468 | AB19: =IF(B19="Capão do Leão","Erro IBGE", IF(AND(U19<=0,M19<=2000000),"Mercado insuficiente", IF(U19<=0,"Limite de expansão", IF(K19<500000,"Performance", IF(M19<=2000000,"Mercado insuficiente","Expansão") ) ) ) ) -> Performance | AC19: =IF(P19=B19,"Oportunidade","Validar") -> Validar
A20: 411820 | B20: Paranaguá | C20: PR | D20: 0 | E20: =COUNTIFS('Contratos assinados '!F:F,'Direcional Expansão'!B20,'Contratos assinados '!J:J, "Assinado por ambos") -> 0 | F20: =COUNTIFS('Contratos assinados '!F:F,'Direcional Expansão'!B20,'Contratos assinados '!J:J,"Aquisição") -> 0 | G20: =COUNTIFS('Contratos assinados '!F:F,'Direcional Expansão'!B20,'Contratos assinados '!J:J,"Ampliação") -> 0 | H20: =COUNTIFS('Contratos assinados '!F:F,'Direcional Expansão'!B20,'Contratos assinados '!J:J,"Assinado por proprietário") -> 0 | I20: =SUM(E20:H20) -> 0 | J20: =IF(D20=0, "-", COUNTIFS('Base Lojas'!B:B, A20, 'Base Lojas'!I:I, ">500000")/D20) -> - | K20: - | L20: 0 | M20: 19242219 | N20: 145829 | O20: =_xlfn.XLOOKUP(A20,Cidades!A:A,Cidades!D:D) -> Entre 100k e 150k | P20: =_xlfn.XLOOKUP(A20,'[1]1° RAIZ'!$A:$A,'[1]1° RAIZ'!$AH:$AH) -> Paranaguá | Q20: =_xlfn.XLOOKUP(A20,'[1]1° RAIZ'!$A:$A,'[1]1° RAIZ'!$AE:$AE) -> Curitiba | R20: 2.8951945e-05 | S20: 0.008228996 | T20: 42 | U20: 9 | V20: 102167.39 | W20: 4.1460404 | X20: 1.4326877 | Y20: 0.24780078 | Z20: 0.33226947 | AA20: 0.68375401 | AB20: =IF(B20="Capão do Leão","Erro IBGE", IF(AND(U20<=0,M20<=2000000),"Mercado insuficiente", IF(U20<=0,"Limite de expansão", IF(K20<500000,"Performance", IF(M20<=2000000,"Mercado insuficiente","Expansão") ) ) ) ) -> Expansão | AC20: =IF(P20=B20,"Oportunidade","Validar") -> Oportunidade
A21: 410420 | B21: Campo Largo | C21: PR | D21: 1 | E21: =COUNTIFS('Contratos assinados '!F:F,'Direcional Expansão'!B21,'Contratos assinados '!J:J, "Assinado por ambos") -> 0 | F21: =COUNTIFS('Contratos assinados '!F:F,'Direcional Expansão'!B21,'Contratos assinados '!J:J,"Aquisição") -> 0 | G21: =COUNTIFS('Contratos assinados '!F:F,'Direcional Expansão'!B21,'Contratos assinados '!J:J,"Ampliação") -> 0 | H21: =COUNTIFS('Contratos assinados '!F:F,'Direcional Expansão'!B21,'Contratos assinados '!J:J,"Assinado por proprietário") -> 0 | I21: =SUM(E21:H21) -> 0 | J21: =IF(D21=0, "-", COUNTIFS('Base Lojas'!B:B, A21, 'Base Lojas'!G:G, ">500000")/D21) -> 0 | K21: 301953.03 | L21: 0.015641302 | M21: 19304852 | N21: 136327 | O21: =_xlfn.XLOOKUP(A21,Cidades!A:A,Cidades!D:D) -> Entre 100k e 150k | P21: =_xlfn.XLOOKUP(A21,'[1]1° RAIZ'!$A:$A,'[1]1° RAIZ'!$AH:$AH) -> Curitiba | Q21: =_xlfn.XLOOKUP(A21,'[1]1° RAIZ'!$A:$A,'[1]1° RAIZ'!$AE:$AE) -> Curitiba | R21: 0.00014896606 | S21: 0.01998374 | T21: 43 | U21: 9 | V21: 44646.152 | W21: 3.8373474 | X21: 1.3776875 | Y21: -0.16186841 | Z21: -0.828746 | AA21: 0.46881749 | AB21: =IF(B21="Capão do Leão","Erro IBGE", IF(AND(U21<=0,M21<=2000000),"Mercado insuficiente", IF(U21<=0,"Limite de expansão", IF(K21<500000,"Performance", IF(M21<=2000000,"Mercado insuficiente","Expansão") ) ) ) ) -> Performance | AC21: =IF(P21=B21,"Oportunidade","Validar") -> Validar
A22: 410830 | B22: Foz do Iguaçu | C22: PR | D22: 10 | E22: =COUNTIFS('Contratos assinados '!F:F,'Direcional Expansão'!B22,'Contratos assinados '!J:J, "Assinado por ambos") -> 0 | F22: =COUNTIFS('Contratos assinados '!F:F,'Direcional Expansão'!B22,'Contratos assinados '!J:J,"Aquisição") -> 0 | G22: =COUNTIFS('Contratos assinados '!F:F,'Direcional Expansão'!B22,'Contratos assinados '!J:J,"Ampliação") -> 0 | H22: =COUNTIFS('Contratos assinados '!F:F,'Direcional Expansão'!B22,'Contratos assinados '!J:J,"Assinado por proprietário") -> 0 | I22: =SUM(E22:H22) -> 0 | J22: =IF(D22=0, "-", COUNTIFS('Base Lojas'!B:B, A22, 'Base Lojas'!G:G, ">500000")/D22) -> 0.3 | K22: 452232.31 | L22: 0.11863706 | M22: 38118976 | N22: 285415 | O22: =_xlfn.XLOOKUP(A22,Cidades!A:A,Cidades!D:D) -> Maior que 200k | P22: =_xlfn.XLOOKUP(A22,'[1]1° RAIZ'!$A:$A,'[1]1° RAIZ'!$AH:$AH) -> Foz do Iguaçu | Q22: =_xlfn.XLOOKUP(A22,'[1]1° RAIZ'!$A:$A,'[1]1° RAIZ'!$AE:$AE) -> Cascavel | R22: 8.3772374e-05 | S22: 0.012008413 | T22: 145 | U22: 8 | V22: 71722.668 | W22: 4.2109551 | X22: 2.9407416 | Y22: -0.18157163 | Z22: 0.22555935 | AA22: 1.2520177 | AB22: =IF(B22="Capão do Leão","Erro IBGE", IF(AND(U22<=0,M22<=2000000),"Mercado insuficiente", IF(U22<=0,"Limite de expansão", IF(K22<500000,"Performance", IF(M22<=2000000,"Mercado insuficiente","Expansão") ) ) ) ) -> Performance | AC22: =IF(P22=B22,"Oportunidade","Validar") -> Oportunidade
A23: 410765 | B23: Fazenda Rio Grande | C23: PR | D23: 1 | E23: =COUNTIFS('Contratos assinados '!F:F,'Direcional Expansão'!B23,'Contratos assinados '!J:J, "Assinado por ambos") -> 0 | F23: =COUNTIFS('Contratos assinados '!F:F,'Direcional Expansão'!B23,'Contratos assinados '!J:J,"Aquisição") -> 0 | G23: =COUNTIFS('Contratos assinados '!F:F,'Direcional Expansão'!B23,'Contratos assinados '!J:J,"Ampliação") -> 0 | H23: =COUNTIFS('Contratos assinados '!F:F,'Direcional Expansão'!B23,'Contratos assinados '!J:J,"Assinado por proprietário") -> 0 | I23: =SUM(E23:H23) -> 0 | J23: =IF(D23=0, "-", COUNTIFS('Base Lojas'!B:B, A23, 'Base Lojas'!G:G, ">500000")/D23) -> 0 | K23: 335285.31 | L23: 0.018299132 | M23: 18322470 | N23: 148873 | O23: =_xlfn.XLOOKUP(A23,Cidades!A:A,Cidades!D:D) -> Entre 100k e 150k | P23: =_xlfn.XLOOKUP(A23,'[1]1° RAIZ'!$A:$A,'[1]1° RAIZ'!$AH:$AH) -> Curitiba | Q23: =_xlfn.XLOOKUP(A23,'[1]1° RAIZ'!$A:$A,'[1]1° RAIZ'!$AE:$AE) -> Curitiba | R23: 0.0004725152 | S23: 0.049679155 | T23: 55 | U23: 8 | V23: 22385.599 | W23: 3.6620235 | X23: 1.4618287 | Y23: 0.28013873 | Z23: -1.9088332 | AA23: 0.44496718 | AB23: =IF(B23="Capão do Leão","Erro IBGE", IF(AND(U23<=0,M23<=2000000),"Mercado insuficiente", IF(U23<=0,"Limite de expansão", IF(K23<500000,"Performance", IF(M23<=2000000,"Mercado insuficiente","Expansão") ) ) ) ) -> Performance | AC23: =IF(P23=B23,"Oportunidade","Validar") -> Validar
A24: 420460 | B24: Criciúma | C24: SC | D24: 7 | E24: =COUNTIFS('Contratos assinados '!F:F,'Direcional Expansão'!B24,'Contratos assinados '!J:J, "Assinado por ambos") -> 1 | F24: =COUNTIFS('Contratos assinados '!F:F,'Direcional Expansão'!B24,'Contratos assinados '!J:J,"Aquisição") -> 0 | G24: =COUNTIFS('Contratos assinados '!F:F,'Direcional Expansão'!B24,'Contratos assinados '!J:J,"Ampliação") -> 0 | H24: =COUNTIFS('Contratos assinados '!F:F,'Direcional Expansão'!B24,'Contratos assinados '!J:J,"Assinado por proprietário") -> 0 | I24: =SUM(E24:H24) -> 1 | J24: =IF(D24=0, "-", COUNTIFS('Base Lojas'!B:B, A24, 'Base Lojas'!G:G, ">500000")/D24) -> 0.42857143 | K24: 444973.28 | L24: 0.086056193 | M24: 36195105 | N24: 214493 | O24: =_xlfn.XLOOKUP(A24,Cidades!A:A,Cidades!D:D) -> Maior que 200k | P24: =_xlfn.XLOOKUP(A24,'[1]1° RAIZ'!$A:$A,'[1]1° RAIZ'!$AH:$AH) -> Criciúma | Q24: =_xlfn.XLOOKUP(A24,'[1]1° RAIZ'!$A:$A,'[1]1° RAIZ'!$AE:$AE) -> Criciúma | R24: 8.4627871e-05 | S24: 0.011365324 | T24: 115 | U24: 7 | V24: 49553.49 | W24: 5.1604455 | X24: 2.5032418 | Y24: 0.20832849 | Z24: -0.22901546 | AA24: 1.0699215 | AB24: =IF(B24="Capão do Leão","Erro IBGE", IF(AND(U24<=0,M24<=2000000),"Mercado insuficiente", IF(U24<=0,"Limite de expansão", IF(K24<500000,"Performance", IF(M24<=2000000,"Mercado insuficiente","Expansão") ) ) ) ) -> Performance | AC24: =IF(P24=B24,"Oportunidade","Validar") -> Oportunidade
A25: 411915 | B25: Pinhais | C25: PR | D25: 1 | E25: =COUNTIFS('Contratos assinados '!F:F,'Direcional Expansão'!B25,'Contratos assinados '!J:J, "Assinado por ambos") -> 0 | F25: =COUNTIFS('Contratos assinados '!F:F,'Direcional Expansão'!B25,'Contratos assinados '!J:J,"Aquisição") -> 0 | G25: =COUNTIFS('Contratos assinados '!F:F,'Direcional Expansão'!B25,'Contratos assinados '!J:J,"Ampliação") -> 0 | H25: =COUNTIFS('Contratos assinados '!F:F,'Direcional Expansão'!B25,'Contratos assinados '!J:J,"Assinado por proprietário") -> 0 | I25: =SUM(E25:H25) -> 0 | J25: =IF(D25=0, "-", COUNTIFS('Base Lojas'!B:B, A25, 'Base Lojas'!G:G, ">500000")/D25) -> 0 | K25: 294273.62 | L25: 0.016034958 | M25: 18352005 | N25: 127019 | O25: =_xlfn.XLOOKUP(A25,Cidades!A:A,Cidades!D:D) -> Entre 100k e 150k | P25: =_xlfn.XLOOKUP(A25,'[1]1° RAIZ'!$A:$A,'[1]1° RAIZ'!$AH:$AH) -> Curitiba | Q25: =_xlfn.XLOOKUP(A25,'[1]1° RAIZ'!$A:$A,'[1]1° RAIZ'!$AE:$AE) -> Curitiba | R25: 6.2304791e-05 | S25: 0.012242356 | T25: 48 | U25: 7 | V25: 67892.111 | W25: 4.5990474 | X25: 1.349847 | Y25: 0.31558757 | Z25: -0.20687327 | AA25: 0.59668061 | AB25: =IF(B25="Capão do Leão","Erro IBGE", IF(AND(U25<=0,M25<=2000000),"Mercado insuficiente", IF(U25<=0,"Limite de expansão", IF(K25<500000,"Performance", IF(M25<=2000000,"Mercado insuficiente","Expansão") ) ) ) ) -> Performance | AC25: =IF(P25=B25,"Oportunidade","Validar") -> Validar
A26: 430060 | B26: Alvorada | C26: RS | D26: 5 | E26: =COUNTIFS('Contratos assinados '!F:F,'Direcional Expansão'!B26,'Contratos assinados '!J:J, "Assinado por ambos") -> 0 | F26: =COUNTIFS('Contratos assinados '!F:F,'Direcional Expansão'!B26,'Contratos assinados '!J:J,"Aquisição") -> 0 | G26: =COUNTIFS('Contratos assinados '!F:F,'Direcional Expansão'!B26,'Contratos assinados '!J:J,"Ampliação") -> 0 | H26: =COUNTIFS('Contratos assinados '!F:F,'Direcional Expansão'!B26,'Contratos assinados '!J:J,"Assinado por proprietário") -> 0 | I26: =SUM(E26:H26) -> 0 | J26: =IF(D26=0, "-", COUNTIFS('Base Lojas'!B:B, A26, 'Base Lojas'!G:G, ">500000")/D26) -> 0.4 | K26: 490164.9 | L26: 0.07999 | M26: 30639136 | N26: 187315 | O26: =_xlfn.XLOOKUP(A26,Cidades!A:A,Cidades!D:D) -> Entre 150k e 200k | P26: =_xlfn.XLOOKUP(A26,'[1]1° RAIZ'!$A:$A,'[1]1° RAIZ'!$AH:$AH) -> Porto Alegre | Q26: =_xlfn.XLOOKUP(A26,'[1]1° RAIZ'!$A:$A,'[1]1° RAIZ'!$AE:$AE) -> Porto Alegre | R26: -3.3699364e-05 | S26: 0.0017537069 | T26: 55 | U26: 7 | V26: 18997.492 | W26: 3.064344 | X26: 1.5643552 | Y26: -1.216041 | Z26: -0.51207539 | AA26: 0.43273097 | AB26: =IF(B26="Capão do Leão","Erro IBGE", IF(AND(U26<=0,M26<=2000000),"Mercado insuficiente", IF(U26<=0,"Limite de expansão", IF(K26<500000,"Performance", IF(M26<=2000000,"Mercado insuficiente","Expansão") ) ) ) ) -> Performance | AC26: =IF(P26=B26,"Oportunidade","Validar") -> Validar
A27: 410040 | B27: Almirante Tamandaré | C27: PR | D27: 0 | E27: =COUNTIFS('Contratos assinados '!F:F,'Direcional Expansão'!B27,'Contratos assinados '!J:J, "Assinado por ambos") -> 0 | F27: =COUNTIFS('Contratos assinados '!F:F,'Direcional Expansão'!B27,'Contratos assinados '!J:J,"Aquisição") -> 0 | G27: =COUNTIFS('Contratos assinados '!F:F,'Direcional Expansão'!B27,'Contratos assinados '!J:J,"Ampliação") -> 0 | H27: =COUNTIFS('Contratos assinados '!F:F,'Direcional Expansão'!B27,'Contratos assinados '!J:J,"Assinado por proprietário") -> 0 | I27: =SUM(E27:H27) -> 0 | J27: =IF(D27=0, "-", COUNTIFS('Base Lojas'!B:B, A27, 'Base Lojas'!I:I, ">500000")/D27) -> - | K27: - | L27: 0 | M27: 15513832 | N27: 119825 | O27: =_xlfn.XLOOKUP(A27,Cidades!A:A,Cidades!D:D) -> Entre 100k e 150k | P27: =_xlfn.XLOOKUP(A27,'[1]1° RAIZ'!$A:$A,'[1]1° RAIZ'!$AH:$AH) -> Curitiba | Q27: =_xlfn.XLOOKUP(A27,'[1]1° RAIZ'!$A:$A,'[1]1° RAIZ'!$AE:$AE) -> Curitiba | R27: 0.00011521836 | S27: 0.015322248 | T27: 24 | U27: 7 | V27: 17286.061 | W27: 3.436899 | X27: 0.936455 | Y27: -0.60054971 | Z27: -1.2010642 | AA27: 0.17525693 | AB27: =IF(B27="Capão do Leão","Erro IBGE", IF(AND(U27<=0,M27<=2000000),"Mercado insuficiente", IF(U27<=0,"Limite de expansão", IF(K27<500000,"Performance", IF(M27<=2000000,"Mercado insuficiente","Expansão") ) ) ) ) -> Expansão | AC27: =IF(P27=B27,"Oportunidade","Validar") -> Validar
A28: 411950 | B28: Piraquara | C28: PR | D28: 0 | E28: =COUNTIFS('Contratos assinados '!F:F,'Direcional Expansão'!B28,'Contratos assinados '!J:J, "Assinado por ambos") -> 0 | F28: =COUNTIFS('Contratos assinados '!F:F,'Direcional Expansão'!B28,'Contratos assinados '!J:J,"Aquisição") -> 0 | G28: =COUNTIFS('Contratos assinados '!F:F,'Direcional Expansão'!B28,'Contratos assinados '!J:J,"Ampliação") -> 0 | H28: =COUNTIFS('Contratos assinados '!F:F,'Direcional Expansão'!B28,'Contratos assinados '!J:J,"Assinado por proprietário") -> 0 | I28: =SUM(E28:H28) -> 0 | J28: =IF(D28=0, "-", COUNTIFS('Base Lojas'!B:B, A28, 'Base Lojas'!I:I, ">500000")/D28) -> - | K28: - | L28: 0 | M28: 13534010 | N28: 118730 | O28: =_xlfn.XLOOKUP(A28,Cidades!A:A,Cidades!D:D) -> Entre 100k e 150k | P28: =_xlfn.XLOOKUP(A28,'[1]1° RAIZ'!$A:$A,'[1]1° RAIZ'!$AH:$AH) -> Curitiba | Q28: =_xlfn.XLOOKUP(A28,'[1]1° RAIZ'!$A:$A,'[1]1° RAIZ'!$AE:$AE) -> Curitiba | R28: 0.00018731505 | S28: 0.021167385 | T28: 30 | U28: 7 | V28: 13696.242 | W28: 3.0673407 | X28: 0.91408895 | Y28: -0.66560603 | Z28: -1.4283861 | AA28: 0.13041566 | AB28: =IF(B28="Capão do Leão","Erro IBGE", IF(AND(U28<=0,M28<=2000000),"Mercado insuficiente", IF(U28<=0,"Limite de expansão", IF(K28<500000,"Performance", IF(M28<=2000000,"Mercado insuficiente","Expansão") ) ) ) ) -> Expansão | AC28: =IF(P28=B28,"Oportunidade","Validar") -> Validar
A29: 412770 | B29: Toledo | C29: PR | D29: 4 | E29: =COUNTIFS('Contratos assinados '!F:F,'Direcional Expansão'!B29,'Contratos assinados '!J:J, "Assinado por ambos") -> 0 | F29: =COUNTIFS('Contratos assinados '!F:F,'Direcional Expansão'!B29,'Contratos assinados '!J:J,"Aquisição") -> 0 | G29: =COUNTIFS('Contratos assinados '!F:F,'Direcional Expansão'!B29,'Contratos assinados '!J:J,"Ampliação") -> 0 | H29: =COUNTIFS('Contratos assinados '!F:F,'Direcional Expansão'!B29,'Contratos assinados '!J:J,"Assinado por proprietário") -> 0 | I29: =SUM(E29:H29) -> 0 | J29: =IF(D29=0, "-", COUNTIFS('Base Lojas'!B:B, A29, 'Base Lojas'!I:I, ">500000")/D29) -> 0.75 | K29: 716649.98 | L29: 0.1224696 | M29: 23406623 | N29: 150470 | O29: =_xlfn.XLOOKUP(A29,Cidades!A:A,Cidades!D:D) -> Entre 150k e 200k | P29: =_xlfn.XLOOKUP(A29,'[1]1° RAIZ'!$A:$A,'[1]1° RAIZ'!$AH:$AH) -> Toledo | Q29: =_xlfn.XLOOKUP(A29,'[1]1° RAIZ'!$A:$A,'[1]1° RAIZ'!$AE:$AE) -> Cascavel | R29: 0.00017981152 | S29: 0.020328581 | T29: 79 | U29: 6 | V29: 52230.744 | W29: 4.2036522 | X29: 1.6689317 | Y29: 0.2588927 | Z29: -0.31793843 | AA29: 0.71173209 | AB29: =IF(B29="Capão do Leão","Erro IBGE", IF(AND(U29<=0,M29<=2000000),"Mercado insuficiente", IF(U29<=0,"Limite de expansão", IF(K29<500000,"Performance", IF(M29<=2000000,"Mercado insuficiente","Expansão") ) ) ) ) -> Expansão | AC29: =IF(P29=B29,"Oportunidade","Validar") -> Oportunidade
A30: 421870 | B30: Tubarão | C30: SC | D30: 1 | E30: =COUNTIFS('Contratos assinados '!F:F,'Direcional Expansão'!B30,'Contratos assinados '!J:J, "Assinado por ambos") -> 0 | F30: =COUNTIFS('Contratos assinados '!F:F,'Direcional Expansão'!B30,'Contratos assinados '!J:J,"Aquisição") -> 0 | G30: =COUNTIFS('Contratos assinados '!F:F,'Direcional Expansão'!B30,'Contratos assinados '!J:J,"Ampliação") -> 0 | H30: =COUNTIFS('Contratos assinados '!F:F,'Direcional Expansão'!B30,'Contratos assinados '!J:J,"Assinado por proprietário") -> 0 | I30: =SUM(E30:H30) -> 0 | J30: =IF(D30=0, "-", COUNTIFS('Base Lojas'!B:B, A30, 'Base Lojas'!G:G, ">500000")/D30) -> 0 | K30: 205659.28 | L30: 0.0097120071 | M30: 21175775 | N30: 110088 | O30: =_xlfn.XLOOKUP(A30,Cidades!A:A,Cidades!D:D) -> Entre 100k e 150k | P30: =_xlfn.XLOOKUP(A30,'[1]1° RAIZ'!$A:$A,'[1]1° RAIZ'!$AH:$AH) -> Tubarão | Q30: =_xlfn.XLOOKUP(A30,'[1]1° RAIZ'!$A:$A,'[1]1° RAIZ'!$AE:$AE) -> Criciúma | R30: 9.5589631e-05 | S30: 0.012052181 | T30: 66 | U30: 6 | V30: 46288.18 | W30: 5.0774551 | X30: 1.4827911 | Y30: 0.37417524 | Z30: -0.599389 | AA30: 0.61692088 | AB30: =IF(B30="Capão do Leão","Erro IBGE", IF(AND(U30<=0,M30<=2000000),"Mercado insuficiente", IF(U30<=0,"Limite de expansão", IF(K30<500000,"Performance", IF(M30<=2000000,"Mercado insuficiente","Expansão") ) ) ) ) -> Performance | AC30: =IF(P30=B30,"Oportunidade","Validar") -> Oportunidade
A31: 411850 | B31: Pato Branco | C31: PR | D31: 0 | E31: =COUNTIFS('Contratos assinados '!F:F,'Direcional Expansão'!B31,'Contratos assinados '!J:J, "Assinado por ambos") -> 0 | F31: =COUNTIFS('Contratos assinados '!F:F,'Direcional Expansão'!B31,'Contratos assinados '!J:J,"Aquisição") -> 0 | G31: =COUNTIFS('Contratos assinados '!F:F,'Direcional Expansão'!B31,'Contratos assinados '!J:J,"Ampliação") -> 0 | H31: =COUNTIFS('Contratos assinados '!F:F,'Direcional Expansão'!B31,'Contratos assinados '!J:J,"Assinado por proprietário") -> 0 | I31: =SUM(E31:H31) -> 0 | J31: =IF(D31=0, "-", COUNTIFS('Base Lojas'!B:B, A31, 'Base Lojas'!I:I, ">500000")/D31) -> - | K31: - | L31: 0 | M31: 14520214 | N31: 91836 | O31: =_xlfn.XLOOKUP(A31,Cidades!A:A,Cidades!D:D) -> Entre 50k e 100k | P31: =_xlfn.XLOOKUP(A31,'[1]1° RAIZ'!$A:$A,'[1]1° RAIZ'!$AH:$AH) -> Pato Branco | Q31: =_xlfn.XLOOKUP(A31,'[1]1° RAIZ'!$A:$A,'[1]1° RAIZ'!$AE:$AE) -> Cascavel | R31: 0.00018489708 | S31: 0.0217162 | T31: 39 | U31: 6 | V31: 52187.733 | W31: 4.8692033 | X31: 1.0990737 | Y31: 0.64686753 | Z31: -0.77770716 | AA31: 0.47239709 | AB31: =IF(B31="Capão do Leão","Erro IBGE", IF(AND(U31<=0,M31<=2000000),"Mercado insuficiente", IF(U31<=0,"Limite de expansão", IF(K31<500000,"Performance", IF(M31<=2000000,"Mercado insuficiente","Expansão") ) ) ) ) -> Expansão | AC31: =IF(P31=B31,"Oportunidade","Validar") -> Oportunidade
A32: 420290 | B32: Brusque | C32: SC | D32: 4 | E32: =COUNTIFS('Contratos assinados '!F:F,'Direcional Expansão'!B32,'Contratos assinados '!J:J, "Assinado por ambos") -> 0 | F32: =COUNTIFS('Contratos assinados '!F:F,'Direcional Expansão'!B32,'Contratos assinados '!J:J,"Aquisição") -> 0 | G32: =COUNTIFS('Contratos assinados '!F:F,'Direcional Expansão'!B32,'Contratos assinados '!J:J,"Ampliação") -> 0 | H32: =COUNTIFS('Contratos assinados '!F:F,'Direcional Expansão'!B32,'Contratos assinados '!J:J,"Assinado por proprietário") -> 0 | I32: =SUM(E32:H32) -> 0 | J32: =IF(D32=0, "-", COUNTIFS('Base Lojas'!B:B, A32, 'Base Lojas'!G:G, ">500000")/D32) -> 0 | K32: 328465.1 | L32: 0.049682323 | M32: 26445229 | N32: 141385 | O32: =_xlfn.XLOOKUP(A32,Cidades!A:A,Cidades!D:D) -> Entre 100k e 150k | P32: =_xlfn.XLOOKUP(A32,'[1]1° RAIZ'!$A:$A,'[1]1° RAIZ'!$AH:$AH) -> Brusque | Q32: =_xlfn.XLOOKUP(A32,'[1]1° RAIZ'!$A:$A,'[1]1° RAIZ'!$AE:$AE) -> Blumenau | R32: 0.00022780454 | S32: 0.022209263 | T32: 61 | U32: 5 | V32: 62954.384 | W32: 5.524978 | X32: 1.6498962 | Y32: 1.0920018 | Z32: -0.44529381 | AA32: 0.80900299 | AB32: =IF(B32="Capão do Leão","Erro IBGE", IF(AND(U32<=0,M32<=2000000),"Mercado insuficiente", IF(U32<=0,"Limite de expansão", IF(K32<500000,"Performance", IF(M32<=2000000,"Mercado insuficiente","Expansão") ) ) ) ) -> Performance | AC32: =IF(P32=B32,"Oportunidade","Validar") -> Oportunidade
A33: 420930 | B33: Lages | C33: SC | D33: 5 | E33: =COUNTIFS('Contratos assinados '!F:F,'Direcional Expansão'!B33,'Contratos assinados '!J:J, "Assinado por ambos") -> 0 | F33: =COUNTIFS('Contratos assinados '!F:F,'Direcional Expansão'!B33,'Contratos assinados '!J:J,"Aquisição") -> 0 | G33: =COUNTIFS('Contratos assinados '!F:F,'Direcional Expansão'!B33,'Contratos assinados '!J:J,"Ampliação") -> 0 | H33: =COUNTIFS('Contratos assinados '!F:F,'Direcional Expansão'!B33,'Contratos assinados '!J:J,"Assinado por proprietário") -> 0 | I33: =SUM(E33:H33) -> 0 | J33: =IF(D33=0, "-", COUNTIFS('Base Lojas'!B:B, A33, 'Base Lojas'!G:G, ">500000")/D33) -> 0.4 | K33: 490487.46 | L33: 0.091539245 | M33: 26791103 | N33: 164981 | O33: =_xlfn.XLOOKUP(A33,Cidades!A:A,Cidades!D:D) -> Entre 150k e 200k | P33: =_xlfn.XLOOKUP(A33,'[1]1° RAIZ'!$A:$A,'[1]1° RAIZ'!$AH:$AH) -> Lages | Q33: =_xlfn.XLOOKUP(A33,'[1]1° RAIZ'!$A:$A,'[1]1° RAIZ'!$AE:$AE) -> Lages | R33: 3.950944e-05 | S33: 0.0075488934 | T33: 115 | U33: 5 | V33: 42716.182 | W33: 4.3835907 | X33: 1.987601 | Y33: -0.18906524 | Z33: -0.21258802 | AA33: 0.79499537 | AB33: =IF(B33="Capão do Leão","Erro IBGE", IF(AND(U33<=0,M33<=2000000),"Mercado insuficiente", IF(U33<=0,"Limite de expansão", IF(K33<500000,"Performance", IF(M33<=2000000,"Mercado insuficiente","Expansão") ) ) ) ) -> Performance | AC33: =IF(P33=B33,"Oportunidade","Validar") -> Oportunidade
A34: 412710 | B34: Telêmaco Borba | C34: PR | D34: 0 | E34: =COUNTIFS('Contratos assinados '!F:F,'Direcional Expansão'!B34,'Contratos assinados '!J:J, "Assinado por ambos") -> 0 | F34: =COUNTIFS('Contratos assinados '!F:F,'Direcional Expansão'!B34,'Contratos assinados '!J:J,"Aquisição") -> 0 | G34: =COUNTIFS('Contratos assinados '!F:F,'Direcional Expansão'!B34,'Contratos assinados '!J:J,"Ampliação") -> 0 | H34: =COUNTIFS('Contratos assinados '!F:F,'Direcional Expansão'!B34,'Contratos assinados '!J:J,"Assinado por proprietário") -> 0 | I34: =SUM(E34:H34) -> 0 | J34: =IF(D34=0, "-", COUNTIFS('Base Lojas'!B:B, A34, 'Base Lojas'!I:I, ">500000")/D34) -> - | K34: - | L34: 0 | M34: 9914555.7 | N34: 75042 | O34: =_xlfn.XLOOKUP(A34,Cidades!A:A,Cidades!D:D) -> Entre 50k e 100k | P34: =_xlfn.XLOOKUP(A34,'[1]1° RAIZ'!$A:$A,'[1]1° RAIZ'!$AH:$AH) -> Telêmaco Borba | Q34: =_xlfn.XLOOKUP(A34,'[1]1° RAIZ'!$A:$A,'[1]1° RAIZ'!$AE:$AE) -> Ponta Grossa | R34: 5.4994585e-05 | S34: 0.009125936 | T34: 30 | U34: 5 | V34: 71362.289 | W34: 3.6791284 | X34: 0.68350388 | Y34: 0.024108936 | Z34: -0.16464125 | AA34: 0.27576468 | AB34: =IF(B34="Capão do Leão","Erro IBGE", IF(AND(U34<=0,M34<=2000000),"Mercado insuficiente", IF(U34<=0,"Limite de expansão", IF(K34<500000,"Performance", IF(M34<=2000000,"Mercado insuficiente","Expansão") ) ) ) ) -> Expansão | AC34: =IF(P34=B34,"Oportunidade","Validar") -> Oportunidade
A35: 420200 | B35: Balneário Camboriú | C35: SC | D35: 5 | E35: =COUNTIFS('Contratos assinados '!F:F,'Direcional Expansão'!B35,'Contratos assinados '!J:J, "Assinado por ambos") -> 1 | F35: =COUNTIFS('Contratos assinados '!F:F,'Direcional Expansão'!B35,'Contratos assinados '!J:J,"Aquisição") -> 0 | G35: =COUNTIFS('Contratos assinados '!F:F,'Direcional Expansão'!B35,'Contratos assinados '!J:J,"Ampliação") -> 1 | H35: =COUNTIFS('Contratos assinados '!F:F,'Direcional Expansão'!B35,'Contratos assinados '!J:J,"Assinado por proprietário") -> 0 | I35: =SUM(E35:H35) -> 2 | J35: =IF(D35=0, "-", COUNTIFS('Base Lojas'!B:B, A35, 'Base Lojas'!I:I, ">500000")/D35) -> 0.4 | K35: 806616.68 | L35: 0.11471087 | M35: 35158687 | N35: 139155 | O35: =_xlfn.XLOOKUP(A35,Cidades!A:A,Cidades!D:D) -> Entre 100k e 150k | P35: =_xlfn.XLOOKUP(A35,'[1]1° RAIZ'!$A:$A,'[1]1° RAIZ'!$AH:$AH) -> Itajaí | Q35: =_xlfn.XLOOKUP(A35,'[1]1° RAIZ'!$A:$A,'[1]1° RAIZ'!$AE:$AE) -> Blumenau | R35: 0.00019610339 | S35: 0.019889433 | T35: 65 | U35: 4 | V35: 54378.59 | W35: 6.9553493 | X35: 1.9334723 | Y35: 1.7233716 | Z35: -0.24266623 | AA35: 1.0437839 | AB35: =IF(B35="Capão do Leão","Erro IBGE", IF(AND(U35<=0,M35<=2000000),"Mercado insuficiente", IF(U35<=0,"Limite de expansão", IF(K35<500000,"Performance", IF(M35<=2000000,"Mercado insuficiente","Expansão") ) ) ) ) -> Expansão | AC35: =IF(P35=B35,"Oportunidade","Validar") -> Validar
A36: 432300 | B36: Viamão | C36: RS | D36: 10 | E36: =COUNTIFS('Contratos assinados '!F:F,'Direcional Expansão'!B36,'Contratos assinados '!J:J, "Assinado por ambos") -> 0 | F36: =COUNTIFS('Contratos assinados '!F:F,'Direcional Expansão'!B36,'Contratos assinados '!J:J,"Aquisição") -> 0 | G36: =COUNTIFS('Contratos assinados '!F:F,'Direcional Expansão'!B36,'Contratos assinados '!J:J,"Ampliação") -> 0 | H36: =COUNTIFS('Contratos assinados '!F:F,'Direcional Expansão'!B36,'Contratos assinados '!J:J,"Assinado por proprietário") -> 0 | I36: =SUM(E36:H36) -> 0 | J36: =IF(D36=0, "-", COUNTIFS('Base Lojas'!B:B, A36, 'Base Lojas'!I:I, ">500000")/D36) -> 0.7 | K36: 570796.94 | L36: 0.15236613 | M36: 37462192 | N36: 224116 | O36: =_xlfn.XLOOKUP(A36,Cidades!A:A,Cidades!D:D) -> Maior que 200k | P36: =_xlfn.XLOOKUP(A36,'[1]1° RAIZ'!$A:$A,'[1]1° RAIZ'!$AH:$AH) -> Porto Alegre | Q36: =_xlfn.XLOOKUP(A36,'[1]1° RAIZ'!$A:$A,'[1]1° RAIZ'!$AE:$AE) -> Porto Alegre | R36: -5.0088274e-05 | S36: 0.00022813512 | T36: 70 | U36: 4 | V36: 20862.851 | W36: 3.515079 | X36: 1.7963636 | Y36: -0.92158162 | Z36: -0.1053324 | AA36: 0.6203581 | AB36: =IF(B36="Capão do Leão","Erro IBGE", IF(AND(U36<=0,M36<=2000000),"Mercado insuficiente", IF(U36<=0,"Limite de expansão", IF(K36<500000,"Performance", IF(M36<=2000000,"Mercado insuficiente","Expansão") ) ) ) ) -> Expansão | AC36: =IF(P36=B36,"Oportunidade","Validar") -> Validar
A37: 421480 | B37: Rio do Sul | C37: SC | D37: 0 | E37: =COUNTIFS('Contratos assinados '!F:F,'Direcional Expansão'!B37,'Contratos assinados '!J:J, "Assinado por ambos") -> 0 | F37: =COUNTIFS('Contratos assinados '!F:F,'Direcional Expansão'!B37,'Contratos assinados '!J:J,"Aquisição") -> 0 | G37: =COUNTIFS('Contratos assinados '!F:F,'Direcional Expansão'!B37,'Contratos assinados '!J:J,"Ampliação") -> 0 | H37: =COUNTIFS('Contratos assinados '!F:F,'Direcional Expansão'!B37,'Contratos assinados '!J:J,"Assinado por proprietário") -> 0 | I37: =SUM(E37:H37) -> 0 | J37: =IF(D37=0, "-", COUNTIFS('Base Lojas'!B:B, A37, 'Base Lojas'!I:I, ">500000")/D37) -> - | K37: - | L37: 0 | M37: 15402738 | N37: 72587 | O37: =_xlfn.XLOOKUP(A37,Cidades!A:A,Cidades!D:D) -> Entre 50k e 100k | P37: =_xlfn.XLOOKUP(A37,'[1]1° RAIZ'!$A:$A,'[1]1° RAIZ'!$AH:$AH) -> Rio do Sul | Q37: =_xlfn.XLOOKUP(A37,'[1]1° RAIZ'!$A:$A,'[1]1° RAIZ'!$AE:$AE) -> Blumenau | R37: 0.00013217669 | S37: 0.016087152 | T37: 42 | U37: 4 | V37: 53526.937 | W37: 5.3408019 | X37: 1.0136017 | Y37: 0.83875508 | Z37: -0.58173168 | AA37: 0.4859897 | AB37: =IF(B37="Capão do Leão","Erro IBGE", IF(AND(U37<=0,M37<=2000000),"Mercado insuficiente", IF(U37<=0,"Limite de expansão", IF(K37<500000,"Performance", IF(M37<=2000000,"Mercado insuficiente","Expansão") ) ) ) ) -> Expansão | AC37: =IF(P37=B37,"Oportunidade","Validar") -> Oportunidade
A38: 410430 | B38: Campo Mourão | C38: PR | D38: 2 | E38: =COUNTIFS('Contratos assinados '!F:F,'Direcional Expansão'!B38,'Contratos assinados '!J:J, "Assinado por ambos") -> 0 | F38: =COUNTIFS('Contratos assinados '!F:F,'Direcional Expansão'!B38,'Contratos assinados '!J:J,"Aquisição") -> 0 | G38: =COUNTIFS('Contratos assinados '!F:F,'Direcional Expansão'!B38,'Contratos assinados '!J:J,"Ampliação") -> 0 | H38: =COUNTIFS('Contratos assinados '!F:F,'Direcional Expansão'!B38,'Contratos assinados '!J:J,"Assinado por proprietário") -> 0 | I38: =SUM(E38:H38) -> 0 | J38: =IF(D38=0, "-", COUNTIFS('Base Lojas'!B:B, A38, 'Base Lojas'!I:I, ">500000")/D38) -> 0.5 | K38: 501535.03 | L38: 0.066502735 | M38: 15083140 | N38: 99432 | O38: =_xlfn.XLOOKUP(A38,Cidades!A:A,Cidades!D:D) -> Entre 50k e 100k | P38: =_xlfn.XLOOKUP(A38,'[1]1° RAIZ'!$A:$A,'[1]1° RAIZ'!$AH:$AH) -> Campo Mourão | Q38: =_xlfn.XLOOKUP(A38,'[1]1° RAIZ'!$A:$A,'[1]1° RAIZ'!$AE:$AE) -> Maringá | R38: 0.00010071336 | S38: 0.014473581 | T38: 43 | U38: 4 | V38: 55545.374 | W38: 4.0864536 | X38: 0.94905437 | Y38: 0.22828438 | Z38: -0.26698713 | AA38: 0.40656196 | AB38: =IF(B38="Capão do Leão","Erro IBGE", IF(AND(U38<=0,M38<=2000000),"Mercado insuficiente", IF(U38<=0,"Limite de expansão", IF(K38<500000,"Performance", IF(M38<=2000000,"Mercado insuficiente","Expansão") ) ) ) ) -> Expansão | AC38: =IF(P38=B38,"Oportunidade","Validar") -> Oportunidade
A39: 420590 | B39: Gaspar | C39: SC | D39: 0 | E39: =COUNTIFS('Contratos assinados '!F:F,'Direcional Expansão'!B39,'Contratos assinados '!J:J, "Assinado por ambos") -> 0 | F39: =COUNTIFS('Contratos assinados '!F:F,'Direcional Expansão'!B39,'Contratos assinados '!J:J,"Aquisição") -> 0 | G39: =COUNTIFS('Contratos assinados '!F:F,'Direcional Expansão'!B39,'Contratos assinados '!J:J,"Ampliação") -> 0 | H39: =COUNTIFS('Contratos assinados '!F:F,'Direcional Expansão'!B39,'Contratos assinados '!J:J,"Assinado por proprietário") -> 0 | I39: =SUM(E39:H39) -> 0 | J39: =IF(D39=0, "-", COUNTIFS('Base Lojas'!B:B, A39, 'Base Lojas'!I:I, ">500000")/D39) -> - | K39: - | L39: 0 | M39: 13722462 | N39: 72570 | O39: =_xlfn.XLOOKUP(A39,Cidades!A:A,Cidades!D:D) -> Entre 50k e 100k | P39: =_xlfn.XLOOKUP(A39,'[1]1° RAIZ'!$A:$A,'[1]1° RAIZ'!$AH:$AH) -> Blumenau | Q39: =_xlfn.XLOOKUP(A39,'[1]1° RAIZ'!$A:$A,'[1]1° RAIZ'!$AE:$AE) -> Blumenau | R39: 0.00017445268 | S39: 0.019226369 | T39: 30 | U39: 4 | V39: 59599.866 | W39: 4.8103239 | X39: 0.83352119 | Y39: 0.76046429 | Z39: -0.58562713 | AA39: 0.39758321 | AB39: =IF(B39="Capão do Leão","Erro IBGE", IF(AND(U39<=0,M39<=2000000),"Mercado insuficiente", IF(U39<=0,"Limite de expansão", IF(K39<500000,"Performance", IF(M39<=2000000,"Mercado insuficiente","Expansão") ) ) ) ) -> Expansão | AC39: =IF(P39=B39,"Oportunidade","Validar") -> Validar
A40: 421580 | B40: São Bento do Sul | C40: SC | D40: 1 | E40: =COUNTIFS('Contratos assinados '!F:F,'Direcional Expansão'!B40,'Contratos assinados '!J:J, "Assinado por ambos") -> 0 | F40: =COUNTIFS('Contratos assinados '!F:F,'Direcional Expansão'!B40,'Contratos assinados '!J:J,"Aquisição") -> 0 | G40: =COUNTIFS('Contratos assinados '!F:F,'Direcional Expansão'!B40,'Contratos assinados '!J:J,"Ampliação") -> 0 | H40: =COUNTIFS('Contratos assinados '!F:F,'Direcional Expansão'!B40,'Contratos assinados '!J:J,"Assinado por proprietário") -> 0 | I40: =SUM(E40:H40) -> 0 | J40: =IF(D40=0, "-", COUNTIFS('Base Lojas'!B:B, A40, 'Base Lojas'!I:I, ">500000")/D40) -> 1 | K40: 512968.37 | L40: 0.037645221 | M40: 13626387 | N40: 83275 | O40: =_xlfn.XLOOKUP(A40,Cidades!A:A,Cidades!D:D) -> Entre 50k e 100k | P40: =_xlfn.XLOOKUP(A40,'[1]1° RAIZ'!$A:$A,'[1]1° RAIZ'!$AH:$AH) -> São Bento do Sul - Rio Negrinho | Q40: =_xlfn.XLOOKUP(A40,'[1]1° RAIZ'!$A:$A,'[1]1° RAIZ'!$AE:$AE) -> Joinville | R40: 8.2934794e-05 | S40: 0.010469137 | T40: 29 | U40: 4 | V40: 60201.782 | W40: 4.5119363 | X40: 0.8119954 | Y40: 0.44217743 | Z40: -0.2334116 | AA40: 0.38281201 | AB40: =IF(B40="Capão do Leão","Erro IBGE", IF(AND(U40<=0,M40<=2000000),"Mercado insuficiente", IF(U40<=0,"Limite de expansão", IF(K40<500000,"Performance", IF(M40<=2000000,"Mercado insuficiente","Expansão") ) ) ) ) -> Expansão | AC40: =IF(P40=B40,"Oportunidade","Validar") -> Validar
...

Sheet Expansão cidades Sem FSJ
A1: Cód | B1: Município | C1: UF | D1: N° FSJ | E1: Ass. por ambos | F1: Aquisição | G1: Ampliação | H1: Assinado por proprietário | I1: Contratos | J1: Venda > 500k | K1: Média Faturamento | L1: %Share | M1: Demanda | N1: População | O1: Porte da cidade | P1: REGIÃO GEOGRÁFICA IMEDIATA | Q1: REGIÃO GEOGRÁFICA INTERMEDIÁRIA | R1: Taxa Crescimento Pop | S1: Taxa Crescimento Dom | T1: Concorrência | U1: Lojas Cabem | V1: PIB | W1: Renda Média Domiciliar (SM) | X1: Fator 1 | Y1: Fator 2 | Z1: Fator 3 | AA1: Ranking | AB1: Status | AC1: Região Imediata
A2: 411990 | B2: Ponta Grossa | C2: PR | D2: 0 | E2: 0 | F2: 0 | G2: 0 | H2: 0 | I2: 0 | J2: - | K2: - | L2: 0 | M2: 52309124 | N2: 358367 | O2: Maior que 200k | P2: Ponta Grossa | Q2: Ponta Grossa | R2: 0.00010790575 | S2: 0.015582368 | T2: 109 | U2: 23 | V2: 58329.645 | W2: 4.495249 | X2: 3.9681546 | Y2: -0.78599628 | Z2: -0.73897544 | AA2: 1.4924571 | AB2: Expansão | AC2: Oportunidade
A3: 411820 | B3: Paranaguá | C3: PR | D3: 0 | E3: 0 | F3: 0 | G3: 0 | H3: 0 | I3: 0 | J3: - | K3: - | L3: 0 | M3: 19242219 | N3: 145829 | O3: Entre 100k e 150k | P3: Paranaguá | Q3: Curitiba | R3: 2.8951945e-05 | S3: 0.008228996 | T3: 42 | U3: 9 | V3: 102167.39 | W3: 4.1460404 | X3: 1.4326877 | Y3: 0.24780078 | Z3: 0.33226947 | AA3: 0.68375401 | AB3: Expansão | AC3: Oportunidade
A4: 411850 | B4: Pato Branco | C4: PR | D4: 0 | E4: 0 | F4: 0 | G4: 0 | H4: 0 | I4: 0 | J4: - | K4: - | L4: 0 | M4: 14520214 | N4: 91836 | O4: Entre 50k e 100k | P4: Pato Branco | Q4: Cascavel | R4: 0.00018489708 | S4: 0.0217162 | T4: 39 | U4: 6 | V4: 52187.733 | W4: 4.8692033 | X4: 1.0990737 | Y4: 0.64686753 | Z4: -0.77770716 | AA4: 0.47239709 | AB4: Expansão | AC4: Oportunidade
A5: 412710 | B5: Telêmaco Borba | C5: PR | D5: 0 | E5: 0 | F5: 0 | G5: 0 | H5: 0 | I5: 0 | J5: - | K5: - | L5: 0 | M5: 9914555.7 | N5: 75042 | O5: Entre 50k e 100k | P5: Telêmaco Borba | Q5: Ponta Grossa | R5: 5.4994585e-05 | S5: 0.009125936 | T5: 30 | U5: 5 | V5: 71362.289 | W5: 3.6791284 | X5: 0.68350388 | Y5: 0.024108936 | Z5: -0.16464125 | AA5: 0.27576468 | AB5: Expansão | AC5: Oportunidade
A6: 421480 | B6: Rio do Sul | C6: SC | D6: 0 | E6: 0 | F6: 0 | G6: 0 | H6: 0 | I6: 0 | J6: - | K6: - | L6: 0 | M6: 15402738 | N6: 72587 | O6: Entre 50k e 100k | P6: Rio do Sul | Q6: Blumenau | R6: 0.00013217669 | S6: 0.016087152 | T6: 42 | U6: 4 | V6: 53526.937 | W6: 5.3408019 | X6: 1.0136017 | Y6: 0.83875508 | Z6: -0.58173168 | AA6: 0.4859897 | AB6: Expansão | AC6: Oportunidade
A7: 421950 | B7: Xanxerê | C7: SC | D7: 0 | E7: 0 | F7: 0 | G7: 0 | H7: 0 | I7: 0 | J7: - | K7: - | L7: 0 | M7: 8584204.1 | N7: 51607 | O7: Entre 50k e 100k | P7: Xanxerê | Q7: Chapecó | R7: 0.00012161993 | S7: 0.017376071 | T7: 31 | U7: 3 | V7: 54797.374 | W7: 4.5281045 | X7: 0.59798918 | Y7: 0.55006792 | Z7: -0.55880519 | AA7: 0.27005269 | AB7: Expansão | AC7: Oportunidade
A8: 412410 | B8: Santo Antônio da Platina | C8: PR | D8: 0 | E8: 0 | F8: 0 | G8: 0 | H8: 0 | I8: 0 | J8: - | K8: - | L8: 0 | M8: 5928799.9 | N8: 44369 | O8: Entre 30k e 50k | P8: Santo Antônio da Platina | Q8: Londrina | R8: 2.9754315e-05 | S8: 0.0079185813 | T8: 16 | U8: 2 | V8: 37107.228 | W8: 3.8145906 | X8: 0.24885006 | Y8: -0.11564311 | Z8: -0.61233358 | AA8: 0.019428494 | AB8: Expansão | AC8: Oportunidade
A9: 420480 | B9: Curitibanos | C9: SC | D9: 0 | E9: 0 | F9: 0 | G9: 0 | H9: 0 | I9: 0 | J9: - | K9: - | L9: 0 | M9: 5670523.2 | N9: 40045 | O9: Entre 30k e 50k | P9: Curitibanos | Q9: Lages | R9: 4.5010832e-05 | S9: 0.0082179844 | T9: 15 | U9: 2 | V9: 50435.189 | W9: 3.4555052 | X9: 0.1838955 | Y9: -0.13127679 | Z9: -0.43063015 | AA9: 0.010259258 | AB9: Expansão | AC9: Oportunidade
A10: 411960 | B10: Pitanga | C10: PR | D10: 0 | E10: 0 | F10: 0 | G10: 0 | H10: 0 | I10: 0 | J10: - | K10: - | L10: 0 | M10: 4062805.8 | N10: 33567 | O10: Entre 30k e 50k | P10: Pitanga | Q10: Guarapuava | R10: 2.144738e-05 | S10: 0.0087584235 | T10: 13 | U10: 2 | V10: 37059.734 | W10: 3.1276303 | X10: 0.075794473 | Y10: -0.43821235 | Z10: -0.61899937 | AA10: -0.10146373 | AB10: Expansão | AC10: Oportunidade
A11: 411150 | B11: Ivaiporã | C11: PR | D11: 0 | E11: 0 | F11: 0 | G11: 0 | H11: 0 | I11: 0 | J11: - | K11: - | L11: 0 | M11: 5085950.4 | N11: 32720 | O11: Entre 30k e 50k | P11: Ivaiporã | Q11: Londrina | R11: 2.1671861e-05 | S11: 0.0068679234 | T11: 11 | U11: 2 | V11: 31748.302 | W11: 3.078098 | X11: 0.064012535 | Y11: -0.53133035 | Z11: -0.68875576 | AA11: -0.12784838 | AB11: Expansão | AC11: Oportunidade
A12: 420850 | B12: Ituporanga | C12: SC | D12: 0 | E12: 0 | F12: 0 | G12: 0 | H12: 0 | I12: 0 | J12: - | K12: - | L12: 0 | M12: 4636897.9 | N12: 26525 | O12: Entre 20k e 30k | P12: Ituporanga | Q12: Blumenau | R12: 0.00013593172 | S12: 0.016513956 | T12: 20 | U12: 1 | V12: 55182.749 | W12: 4.269716 | X12: 0.2273939 | Y12: 0.57000236 | Z12: -0.54207804 | AA12: 0.11700263 | AB12: Expansão | AC12: Oportunidade
A13: 410970 | B13: Ibaiti | C13: PR | D13: 0 | E13: 0 | F13: 0 | G13: 0 | H13: 0 | I13: 0 | J13: - | K13: - | L13: 0 | M13: 3843194.1 | N13: 28830 | O13: Entre 20k e 30k | P13: Ibaiti | Q13: Londrina | R13: 2.8070769e-06 | S13: 0.0050148489 | T13: 10 | U13: 1 | V13: 33569.07 | W13: 3.9221118 | X13: 0.072477997 | Y13: -0.092448073 | Z13: -0.58826772 | AA13: -0.049598682 | AB13: Expansão | AC13: Oportunidade
... A32: 411125 | B32: Itaperuçu | C32: PR | D32: 0 | E32: 0 | F32: 0 | G32: 0 | H32: 0 | I32: 0 | J32: - | K32: - | L32: 0 | M32: 3716137.4 | N32: 31217 | O32: Entre 30k e 50k | P32: Curitiba | Q32: Curitiba | R32: 0.00020760736 | S32: 0.024760696 | T32: 9 | U32: 2 | V32: 21112.528 | W32: 2.5430769 | X32: -0.019039875 | Y32: -0.453112 | Z32: -1.3072743 | AA32: -0.22257227 | AB32: Expansão | AC32: Validar

Sheet Expansão cidades Com FSJ
